[2024-12-16T18:31:39.116+0000] {processor.py:157} INFO - Started process (PID=33) to work on /opt/airflow/dags/scripts/kafka_pubsub.py
[2024-12-16T18:31:39.117+0000] {processor.py:826} INFO - Processing file /opt/airflow/dags/scripts/kafka_pubsub.py for tasks to queue
[2024-12-16T18:31:39.119+0000] {logging_mixin.py:150} INFO - [2024-12-16T18:31:39.118+0000] {dagbag.py:541} INFO - Filling up the DagBag from /opt/airflow/dags/scripts/kafka_pubsub.py
[2024-12-16T18:31:39.524+0000] {logging_mixin.py:150} INFO - [2024-12-16T18:31:39.514+0000] {dagbag.py:350} ERROR - Failed to import: /opt/airflow/dags/scripts/kafka_pubsub.py
Traceback (most recent call last):
  File "/home/airflow/.local/lib/python3.8/site-packages/airflow/models/dagbag.py", line 346, in parse
    loader.exec_module(new_module)
  File "<frozen importlib._bootstrap_external>", line 843, in exec_module
  File "<frozen importlib._bootstrap>", line 219, in _call_with_frames_removed
  File "/opt/airflow/dags/scripts/kafka_pubsub.py", line 16, in <module>
    publisher = pubsub_v1.PublisherClient()
  File "/home/airflow/.local/lib/python3.8/site-packages/google/cloud/pubsub_v1/publisher/client.py", line 139, in __init__
    super().__init__(**kwargs)
  File "/home/airflow/.local/lib/python3.8/site-packages/google/pubsub_v1/services/publisher/client.py", line 492, in __init__
    self._transport = Transport(
  File "/home/airflow/.local/lib/python3.8/site-packages/google/pubsub_v1/services/publisher/transports/grpc.py", line 153, in __init__
    super().__init__(
  File "/home/airflow/.local/lib/python3.8/site-packages/google/pubsub_v1/services/publisher/transports/base.py", line 104, in __init__
    credentials, _ = google.auth.default(
  File "/home/airflow/.local/lib/python3.8/site-packages/google/auth/_default.py", line 659, in default
    credentials, project_id = checker()
  File "/home/airflow/.local/lib/python3.8/site-packages/google/auth/_default.py", line 652, in <lambda>
    lambda: _get_explicit_environ_credentials(quota_project_id=quota_project_id),
  File "/home/airflow/.local/lib/python3.8/site-packages/google/auth/_default.py", line 272, in _get_explicit_environ_credentials
    credentials, project_id = load_credentials_from_file(
  File "/home/airflow/.local/lib/python3.8/site-packages/google/auth/_default.py", line 116, in load_credentials_from_file
    raise exceptions.DefaultCredentialsError(
google.auth.exceptions.DefaultCredentialsError: File /Users/megwed./Desktop/airflow_local/ready-de-25-f50d96fb2977.json was not found.
[2024-12-16T18:31:39.525+0000] {processor.py:838} WARNING - No viable dags retrieved from /opt/airflow/dags/scripts/kafka_pubsub.py
[2024-12-16T18:31:39.568+0000] {processor.py:179} INFO - Processing /opt/airflow/dags/scripts/kafka_pubsub.py took 0.457 seconds
[2024-12-16T18:32:10.381+0000] {processor.py:157} INFO - Started process (PID=43) to work on /opt/airflow/dags/scripts/kafka_pubsub.py
[2024-12-16T18:32:10.382+0000] {processor.py:826} INFO - Processing file /opt/airflow/dags/scripts/kafka_pubsub.py for tasks to queue
[2024-12-16T18:32:10.383+0000] {logging_mixin.py:150} INFO - [2024-12-16T18:32:10.383+0000] {dagbag.py:541} INFO - Filling up the DagBag from /opt/airflow/dags/scripts/kafka_pubsub.py
[2024-12-16T18:32:10.522+0000] {logging_mixin.py:150} INFO - [2024-12-16T18:32:10.519+0000] {dagbag.py:350} ERROR - Failed to import: /opt/airflow/dags/scripts/kafka_pubsub.py
Traceback (most recent call last):
  File "/home/airflow/.local/lib/python3.8/site-packages/airflow/models/dagbag.py", line 346, in parse
    loader.exec_module(new_module)
  File "<frozen importlib._bootstrap_external>", line 843, in exec_module
  File "<frozen importlib._bootstrap>", line 219, in _call_with_frames_removed
  File "/opt/airflow/dags/scripts/kafka_pubsub.py", line 16, in <module>
    publisher = pubsub_v1.PublisherClient()
  File "/home/airflow/.local/lib/python3.8/site-packages/google/cloud/pubsub_v1/publisher/client.py", line 139, in __init__
    super().__init__(**kwargs)
  File "/home/airflow/.local/lib/python3.8/site-packages/google/pubsub_v1/services/publisher/client.py", line 492, in __init__
    self._transport = Transport(
  File "/home/airflow/.local/lib/python3.8/site-packages/google/pubsub_v1/services/publisher/transports/grpc.py", line 153, in __init__
    super().__init__(
  File "/home/airflow/.local/lib/python3.8/site-packages/google/pubsub_v1/services/publisher/transports/base.py", line 104, in __init__
    credentials, _ = google.auth.default(
  File "/home/airflow/.local/lib/python3.8/site-packages/google/auth/_default.py", line 659, in default
    credentials, project_id = checker()
  File "/home/airflow/.local/lib/python3.8/site-packages/google/auth/_default.py", line 652, in <lambda>
    lambda: _get_explicit_environ_credentials(quota_project_id=quota_project_id),
  File "/home/airflow/.local/lib/python3.8/site-packages/google/auth/_default.py", line 272, in _get_explicit_environ_credentials
    credentials, project_id = load_credentials_from_file(
  File "/home/airflow/.local/lib/python3.8/site-packages/google/auth/_default.py", line 116, in load_credentials_from_file
    raise exceptions.DefaultCredentialsError(
google.auth.exceptions.DefaultCredentialsError: File /Users/megwed./Desktop/airflow_local/ready-de-25-f50d96fb2977.json was not found.
[2024-12-16T18:32:10.522+0000] {processor.py:838} WARNING - No viable dags retrieved from /opt/airflow/dags/scripts/kafka_pubsub.py
[2024-12-16T18:32:10.538+0000] {processor.py:179} INFO - Processing /opt/airflow/dags/scripts/kafka_pubsub.py took 0.160 seconds
[2024-12-16T18:33:23.558+0000] {processor.py:157} INFO - Started process (PID=32) to work on /opt/airflow/dags/scripts/kafka_pubsub.py
[2024-12-16T18:33:23.562+0000] {processor.py:826} INFO - Processing file /opt/airflow/dags/scripts/kafka_pubsub.py for tasks to queue
[2024-12-16T18:33:23.566+0000] {logging_mixin.py:150} INFO - [2024-12-16T18:33:23.566+0000] {dagbag.py:541} INFO - Filling up the DagBag from /opt/airflow/dags/scripts/kafka_pubsub.py
[2024-12-16T18:33:24.292+0000] {logging_mixin.py:150} INFO - [2024-12-16T18:33:24.270+0000] {dagbag.py:350} ERROR - Failed to import: /opt/airflow/dags/scripts/kafka_pubsub.py
Traceback (most recent call last):
  File "/home/airflow/.local/lib/python3.8/site-packages/airflow/models/dagbag.py", line 346, in parse
    loader.exec_module(new_module)
  File "<frozen importlib._bootstrap_external>", line 843, in exec_module
  File "<frozen importlib._bootstrap>", line 219, in _call_with_frames_removed
  File "/opt/airflow/dags/scripts/kafka_pubsub.py", line 16, in <module>
    publisher = pubsub_v1.PublisherClient()
  File "/home/airflow/.local/lib/python3.8/site-packages/google/cloud/pubsub_v1/publisher/client.py", line 139, in __init__
    super().__init__(**kwargs)
  File "/home/airflow/.local/lib/python3.8/site-packages/google/pubsub_v1/services/publisher/client.py", line 492, in __init__
    self._transport = Transport(
  File "/home/airflow/.local/lib/python3.8/site-packages/google/pubsub_v1/services/publisher/transports/grpc.py", line 153, in __init__
    super().__init__(
  File "/home/airflow/.local/lib/python3.8/site-packages/google/pubsub_v1/services/publisher/transports/base.py", line 104, in __init__
    credentials, _ = google.auth.default(
  File "/home/airflow/.local/lib/python3.8/site-packages/google/auth/_default.py", line 659, in default
    credentials, project_id = checker()
  File "/home/airflow/.local/lib/python3.8/site-packages/google/auth/_default.py", line 652, in <lambda>
    lambda: _get_explicit_environ_credentials(quota_project_id=quota_project_id),
  File "/home/airflow/.local/lib/python3.8/site-packages/google/auth/_default.py", line 272, in _get_explicit_environ_credentials
    credentials, project_id = load_credentials_from_file(
  File "/home/airflow/.local/lib/python3.8/site-packages/google/auth/_default.py", line 116, in load_credentials_from_file
    raise exceptions.DefaultCredentialsError(
google.auth.exceptions.DefaultCredentialsError: File /Users/megwed./Desktop/airflow_local/ready-de-25-f50d96fb2977.json was not found.
[2024-12-16T18:33:24.293+0000] {processor.py:838} WARNING - No viable dags retrieved from /opt/airflow/dags/scripts/kafka_pubsub.py
[2024-12-16T18:33:24.413+0000] {processor.py:179} INFO - Processing /opt/airflow/dags/scripts/kafka_pubsub.py took 0.867 seconds
[2024-12-16T18:33:54.945+0000] {processor.py:157} INFO - Started process (PID=42) to work on /opt/airflow/dags/scripts/kafka_pubsub.py
[2024-12-16T18:33:54.947+0000] {processor.py:826} INFO - Processing file /opt/airflow/dags/scripts/kafka_pubsub.py for tasks to queue
[2024-12-16T18:33:54.949+0000] {logging_mixin.py:150} INFO - [2024-12-16T18:33:54.948+0000] {dagbag.py:541} INFO - Filling up the DagBag from /opt/airflow/dags/scripts/kafka_pubsub.py
[2024-12-16T18:33:55.058+0000] {logging_mixin.py:150} INFO - [2024-12-16T18:33:55.053+0000] {dagbag.py:350} ERROR - Failed to import: /opt/airflow/dags/scripts/kafka_pubsub.py
Traceback (most recent call last):
  File "/home/airflow/.local/lib/python3.8/site-packages/airflow/models/dagbag.py", line 346, in parse
    loader.exec_module(new_module)
  File "<frozen importlib._bootstrap_external>", line 843, in exec_module
  File "<frozen importlib._bootstrap>", line 219, in _call_with_frames_removed
  File "/opt/airflow/dags/scripts/kafka_pubsub.py", line 16, in <module>
    publisher = pubsub_v1.PublisherClient()
  File "/home/airflow/.local/lib/python3.8/site-packages/google/cloud/pubsub_v1/publisher/client.py", line 139, in __init__
    super().__init__(**kwargs)
  File "/home/airflow/.local/lib/python3.8/site-packages/google/pubsub_v1/services/publisher/client.py", line 492, in __init__
    self._transport = Transport(
  File "/home/airflow/.local/lib/python3.8/site-packages/google/pubsub_v1/services/publisher/transports/grpc.py", line 153, in __init__
    super().__init__(
  File "/home/airflow/.local/lib/python3.8/site-packages/google/pubsub_v1/services/publisher/transports/base.py", line 104, in __init__
    credentials, _ = google.auth.default(
  File "/home/airflow/.local/lib/python3.8/site-packages/google/auth/_default.py", line 659, in default
    credentials, project_id = checker()
  File "/home/airflow/.local/lib/python3.8/site-packages/google/auth/_default.py", line 652, in <lambda>
    lambda: _get_explicit_environ_credentials(quota_project_id=quota_project_id),
  File "/home/airflow/.local/lib/python3.8/site-packages/google/auth/_default.py", line 272, in _get_explicit_environ_credentials
    credentials, project_id = load_credentials_from_file(
  File "/home/airflow/.local/lib/python3.8/site-packages/google/auth/_default.py", line 116, in load_credentials_from_file
    raise exceptions.DefaultCredentialsError(
google.auth.exceptions.DefaultCredentialsError: File /Users/megwed./Desktop/airflow_local/ready-de-25-f50d96fb2977.json was not found.
[2024-12-16T18:33:55.058+0000] {processor.py:838} WARNING - No viable dags retrieved from /opt/airflow/dags/scripts/kafka_pubsub.py
[2024-12-16T18:33:55.078+0000] {processor.py:179} INFO - Processing /opt/airflow/dags/scripts/kafka_pubsub.py took 0.135 seconds
[2024-12-16T18:34:25.529+0000] {processor.py:157} INFO - Started process (PID=52) to work on /opt/airflow/dags/scripts/kafka_pubsub.py
[2024-12-16T18:34:25.532+0000] {processor.py:826} INFO - Processing file /opt/airflow/dags/scripts/kafka_pubsub.py for tasks to queue
[2024-12-16T18:34:25.534+0000] {logging_mixin.py:150} INFO - [2024-12-16T18:34:25.534+0000] {dagbag.py:541} INFO - Filling up the DagBag from /opt/airflow/dags/scripts/kafka_pubsub.py
[2024-12-16T18:34:25.843+0000] {logging_mixin.py:150} INFO - [2024-12-16T18:34:25.840+0000] {dagbag.py:350} ERROR - Failed to import: /opt/airflow/dags/scripts/kafka_pubsub.py
Traceback (most recent call last):
  File "/home/airflow/.local/lib/python3.8/site-packages/airflow/models/dagbag.py", line 346, in parse
    loader.exec_module(new_module)
  File "<frozen importlib._bootstrap_external>", line 843, in exec_module
  File "<frozen importlib._bootstrap>", line 219, in _call_with_frames_removed
  File "/opt/airflow/dags/scripts/kafka_pubsub.py", line 16, in <module>
    publisher = pubsub_v1.PublisherClient()
  File "/home/airflow/.local/lib/python3.8/site-packages/google/cloud/pubsub_v1/publisher/client.py", line 139, in __init__
    super().__init__(**kwargs)
  File "/home/airflow/.local/lib/python3.8/site-packages/google/pubsub_v1/services/publisher/client.py", line 492, in __init__
    self._transport = Transport(
  File "/home/airflow/.local/lib/python3.8/site-packages/google/pubsub_v1/services/publisher/transports/grpc.py", line 153, in __init__
    super().__init__(
  File "/home/airflow/.local/lib/python3.8/site-packages/google/pubsub_v1/services/publisher/transports/base.py", line 104, in __init__
    credentials, _ = google.auth.default(
  File "/home/airflow/.local/lib/python3.8/site-packages/google/auth/_default.py", line 659, in default
    credentials, project_id = checker()
  File "/home/airflow/.local/lib/python3.8/site-packages/google/auth/_default.py", line 652, in <lambda>
    lambda: _get_explicit_environ_credentials(quota_project_id=quota_project_id),
  File "/home/airflow/.local/lib/python3.8/site-packages/google/auth/_default.py", line 272, in _get_explicit_environ_credentials
    credentials, project_id = load_credentials_from_file(
  File "/home/airflow/.local/lib/python3.8/site-packages/google/auth/_default.py", line 116, in load_credentials_from_file
    raise exceptions.DefaultCredentialsError(
google.auth.exceptions.DefaultCredentialsError: File /Users/megwed./Desktop/airflow_local/ready-de-25-f50d96fb2977.json was not found.
[2024-12-16T18:34:25.843+0000] {processor.py:838} WARNING - No viable dags retrieved from /opt/airflow/dags/scripts/kafka_pubsub.py
[2024-12-16T18:34:25.858+0000] {processor.py:179} INFO - Processing /opt/airflow/dags/scripts/kafka_pubsub.py took 0.335 seconds
[2024-12-16T18:34:56.277+0000] {processor.py:157} INFO - Started process (PID=62) to work on /opt/airflow/dags/scripts/kafka_pubsub.py
[2024-12-16T18:34:56.279+0000] {processor.py:826} INFO - Processing file /opt/airflow/dags/scripts/kafka_pubsub.py for tasks to queue
[2024-12-16T18:34:56.280+0000] {logging_mixin.py:150} INFO - [2024-12-16T18:34:56.280+0000] {dagbag.py:541} INFO - Filling up the DagBag from /opt/airflow/dags/scripts/kafka_pubsub.py
[2024-12-16T18:34:56.537+0000] {logging_mixin.py:150} INFO - [2024-12-16T18:34:56.533+0000] {dagbag.py:350} ERROR - Failed to import: /opt/airflow/dags/scripts/kafka_pubsub.py
Traceback (most recent call last):
  File "/home/airflow/.local/lib/python3.8/site-packages/airflow/models/dagbag.py", line 346, in parse
    loader.exec_module(new_module)
  File "<frozen importlib._bootstrap_external>", line 843, in exec_module
  File "<frozen importlib._bootstrap>", line 219, in _call_with_frames_removed
  File "/opt/airflow/dags/scripts/kafka_pubsub.py", line 16, in <module>
    publisher = pubsub_v1.PublisherClient()
  File "/home/airflow/.local/lib/python3.8/site-packages/google/cloud/pubsub_v1/publisher/client.py", line 139, in __init__
    super().__init__(**kwargs)
  File "/home/airflow/.local/lib/python3.8/site-packages/google/pubsub_v1/services/publisher/client.py", line 492, in __init__
    self._transport = Transport(
  File "/home/airflow/.local/lib/python3.8/site-packages/google/pubsub_v1/services/publisher/transports/grpc.py", line 153, in __init__
    super().__init__(
  File "/home/airflow/.local/lib/python3.8/site-packages/google/pubsub_v1/services/publisher/transports/base.py", line 104, in __init__
    credentials, _ = google.auth.default(
  File "/home/airflow/.local/lib/python3.8/site-packages/google/auth/_default.py", line 659, in default
    credentials, project_id = checker()
  File "/home/airflow/.local/lib/python3.8/site-packages/google/auth/_default.py", line 652, in <lambda>
    lambda: _get_explicit_environ_credentials(quota_project_id=quota_project_id),
  File "/home/airflow/.local/lib/python3.8/site-packages/google/auth/_default.py", line 272, in _get_explicit_environ_credentials
    credentials, project_id = load_credentials_from_file(
  File "/home/airflow/.local/lib/python3.8/site-packages/google/auth/_default.py", line 116, in load_credentials_from_file
    raise exceptions.DefaultCredentialsError(
google.auth.exceptions.DefaultCredentialsError: File /Users/megwed./Desktop/airflow_local/ready-de-25-f50d96fb2977.json was not found.
[2024-12-16T18:34:56.538+0000] {processor.py:838} WARNING - No viable dags retrieved from /opt/airflow/dags/scripts/kafka_pubsub.py
[2024-12-16T18:34:56.553+0000] {processor.py:179} INFO - Processing /opt/airflow/dags/scripts/kafka_pubsub.py took 0.280 seconds
[2024-12-16T18:35:26.991+0000] {processor.py:157} INFO - Started process (PID=72) to work on /opt/airflow/dags/scripts/kafka_pubsub.py
[2024-12-16T18:35:26.992+0000] {processor.py:826} INFO - Processing file /opt/airflow/dags/scripts/kafka_pubsub.py for tasks to queue
[2024-12-16T18:35:26.994+0000] {logging_mixin.py:150} INFO - [2024-12-16T18:35:26.993+0000] {dagbag.py:541} INFO - Filling up the DagBag from /opt/airflow/dags/scripts/kafka_pubsub.py
[2024-12-16T18:35:27.241+0000] {logging_mixin.py:150} INFO - [2024-12-16T18:35:27.238+0000] {dagbag.py:350} ERROR - Failed to import: /opt/airflow/dags/scripts/kafka_pubsub.py
Traceback (most recent call last):
  File "/home/airflow/.local/lib/python3.8/site-packages/airflow/models/dagbag.py", line 346, in parse
    loader.exec_module(new_module)
  File "<frozen importlib._bootstrap_external>", line 843, in exec_module
  File "<frozen importlib._bootstrap>", line 219, in _call_with_frames_removed
  File "/opt/airflow/dags/scripts/kafka_pubsub.py", line 16, in <module>
    publisher = pubsub_v1.PublisherClient()
  File "/home/airflow/.local/lib/python3.8/site-packages/google/cloud/pubsub_v1/publisher/client.py", line 139, in __init__
    super().__init__(**kwargs)
  File "/home/airflow/.local/lib/python3.8/site-packages/google/pubsub_v1/services/publisher/client.py", line 492, in __init__
    self._transport = Transport(
  File "/home/airflow/.local/lib/python3.8/site-packages/google/pubsub_v1/services/publisher/transports/grpc.py", line 153, in __init__
    super().__init__(
  File "/home/airflow/.local/lib/python3.8/site-packages/google/pubsub_v1/services/publisher/transports/base.py", line 104, in __init__
    credentials, _ = google.auth.default(
  File "/home/airflow/.local/lib/python3.8/site-packages/google/auth/_default.py", line 659, in default
    credentials, project_id = checker()
  File "/home/airflow/.local/lib/python3.8/site-packages/google/auth/_default.py", line 652, in <lambda>
    lambda: _get_explicit_environ_credentials(quota_project_id=quota_project_id),
  File "/home/airflow/.local/lib/python3.8/site-packages/google/auth/_default.py", line 272, in _get_explicit_environ_credentials
    credentials, project_id = load_credentials_from_file(
  File "/home/airflow/.local/lib/python3.8/site-packages/google/auth/_default.py", line 116, in load_credentials_from_file
    raise exceptions.DefaultCredentialsError(
google.auth.exceptions.DefaultCredentialsError: File /Users/megwed./Desktop/airflow_local/ready-de-25-f50d96fb2977.json was not found.
[2024-12-16T18:35:27.242+0000] {processor.py:838} WARNING - No viable dags retrieved from /opt/airflow/dags/scripts/kafka_pubsub.py
[2024-12-16T18:35:27.254+0000] {processor.py:179} INFO - Processing /opt/airflow/dags/scripts/kafka_pubsub.py took 0.269 seconds
[2024-12-16T18:35:57.764+0000] {processor.py:157} INFO - Started process (PID=82) to work on /opt/airflow/dags/scripts/kafka_pubsub.py
[2024-12-16T18:35:57.765+0000] {processor.py:826} INFO - Processing file /opt/airflow/dags/scripts/kafka_pubsub.py for tasks to queue
[2024-12-16T18:35:57.766+0000] {logging_mixin.py:150} INFO - [2024-12-16T18:35:57.765+0000] {dagbag.py:541} INFO - Filling up the DagBag from /opt/airflow/dags/scripts/kafka_pubsub.py
[2024-12-16T18:35:58.103+0000] {logging_mixin.py:150} INFO - [2024-12-16T18:35:58.100+0000] {dagbag.py:350} ERROR - Failed to import: /opt/airflow/dags/scripts/kafka_pubsub.py
Traceback (most recent call last):
  File "/home/airflow/.local/lib/python3.8/site-packages/airflow/models/dagbag.py", line 346, in parse
    loader.exec_module(new_module)
  File "<frozen importlib._bootstrap_external>", line 843, in exec_module
  File "<frozen importlib._bootstrap>", line 219, in _call_with_frames_removed
  File "/opt/airflow/dags/scripts/kafka_pubsub.py", line 16, in <module>
    publisher = pubsub_v1.PublisherClient()
  File "/home/airflow/.local/lib/python3.8/site-packages/google/cloud/pubsub_v1/publisher/client.py", line 139, in __init__
    super().__init__(**kwargs)
  File "/home/airflow/.local/lib/python3.8/site-packages/google/pubsub_v1/services/publisher/client.py", line 492, in __init__
    self._transport = Transport(
  File "/home/airflow/.local/lib/python3.8/site-packages/google/pubsub_v1/services/publisher/transports/grpc.py", line 153, in __init__
    super().__init__(
  File "/home/airflow/.local/lib/python3.8/site-packages/google/pubsub_v1/services/publisher/transports/base.py", line 104, in __init__
    credentials, _ = google.auth.default(
  File "/home/airflow/.local/lib/python3.8/site-packages/google/auth/_default.py", line 659, in default
    credentials, project_id = checker()
  File "/home/airflow/.local/lib/python3.8/site-packages/google/auth/_default.py", line 652, in <lambda>
    lambda: _get_explicit_environ_credentials(quota_project_id=quota_project_id),
  File "/home/airflow/.local/lib/python3.8/site-packages/google/auth/_default.py", line 272, in _get_explicit_environ_credentials
    credentials, project_id = load_credentials_from_file(
  File "/home/airflow/.local/lib/python3.8/site-packages/google/auth/_default.py", line 116, in load_credentials_from_file
    raise exceptions.DefaultCredentialsError(
google.auth.exceptions.DefaultCredentialsError: File /Users/megwed./Desktop/airflow_local/ready-de-25-f50d96fb2977.json was not found.
[2024-12-16T18:35:58.103+0000] {processor.py:838} WARNING - No viable dags retrieved from /opt/airflow/dags/scripts/kafka_pubsub.py
[2024-12-16T18:35:58.120+0000] {processor.py:179} INFO - Processing /opt/airflow/dags/scripts/kafka_pubsub.py took 0.361 seconds
[2024-12-16T18:36:28.630+0000] {processor.py:157} INFO - Started process (PID=92) to work on /opt/airflow/dags/scripts/kafka_pubsub.py
[2024-12-16T18:36:28.632+0000] {processor.py:826} INFO - Processing file /opt/airflow/dags/scripts/kafka_pubsub.py for tasks to queue
[2024-12-16T18:36:28.632+0000] {logging_mixin.py:150} INFO - [2024-12-16T18:36:28.632+0000] {dagbag.py:541} INFO - Filling up the DagBag from /opt/airflow/dags/scripts/kafka_pubsub.py
[2024-12-16T18:36:28.876+0000] {logging_mixin.py:150} INFO - [2024-12-16T18:36:28.873+0000] {dagbag.py:350} ERROR - Failed to import: /opt/airflow/dags/scripts/kafka_pubsub.py
Traceback (most recent call last):
  File "/home/airflow/.local/lib/python3.8/site-packages/airflow/models/dagbag.py", line 346, in parse
    loader.exec_module(new_module)
  File "<frozen importlib._bootstrap_external>", line 843, in exec_module
  File "<frozen importlib._bootstrap>", line 219, in _call_with_frames_removed
  File "/opt/airflow/dags/scripts/kafka_pubsub.py", line 16, in <module>
    publisher = pubsub_v1.PublisherClient()
  File "/home/airflow/.local/lib/python3.8/site-packages/google/cloud/pubsub_v1/publisher/client.py", line 139, in __init__
    super().__init__(**kwargs)
  File "/home/airflow/.local/lib/python3.8/site-packages/google/pubsub_v1/services/publisher/client.py", line 492, in __init__
    self._transport = Transport(
  File "/home/airflow/.local/lib/python3.8/site-packages/google/pubsub_v1/services/publisher/transports/grpc.py", line 153, in __init__
    super().__init__(
  File "/home/airflow/.local/lib/python3.8/site-packages/google/pubsub_v1/services/publisher/transports/base.py", line 104, in __init__
    credentials, _ = google.auth.default(
  File "/home/airflow/.local/lib/python3.8/site-packages/google/auth/_default.py", line 659, in default
    credentials, project_id = checker()
  File "/home/airflow/.local/lib/python3.8/site-packages/google/auth/_default.py", line 652, in <lambda>
    lambda: _get_explicit_environ_credentials(quota_project_id=quota_project_id),
  File "/home/airflow/.local/lib/python3.8/site-packages/google/auth/_default.py", line 272, in _get_explicit_environ_credentials
    credentials, project_id = load_credentials_from_file(
  File "/home/airflow/.local/lib/python3.8/site-packages/google/auth/_default.py", line 116, in load_credentials_from_file
    raise exceptions.DefaultCredentialsError(
google.auth.exceptions.DefaultCredentialsError: File /Users/megwed./Desktop/airflow_local/ready-de-25-f50d96fb2977.json was not found.
[2024-12-16T18:36:28.876+0000] {processor.py:838} WARNING - No viable dags retrieved from /opt/airflow/dags/scripts/kafka_pubsub.py
[2024-12-16T18:36:28.887+0000] {processor.py:179} INFO - Processing /opt/airflow/dags/scripts/kafka_pubsub.py took 0.260 seconds
[2024-12-16T18:36:59.351+0000] {processor.py:157} INFO - Started process (PID=102) to work on /opt/airflow/dags/scripts/kafka_pubsub.py
[2024-12-16T18:36:59.353+0000] {processor.py:826} INFO - Processing file /opt/airflow/dags/scripts/kafka_pubsub.py for tasks to queue
[2024-12-16T18:36:59.354+0000] {logging_mixin.py:150} INFO - [2024-12-16T18:36:59.354+0000] {dagbag.py:541} INFO - Filling up the DagBag from /opt/airflow/dags/scripts/kafka_pubsub.py
[2024-12-16T18:36:59.621+0000] {logging_mixin.py:150} INFO - [2024-12-16T18:36:59.618+0000] {dagbag.py:350} ERROR - Failed to import: /opt/airflow/dags/scripts/kafka_pubsub.py
Traceback (most recent call last):
  File "/home/airflow/.local/lib/python3.8/site-packages/airflow/models/dagbag.py", line 346, in parse
    loader.exec_module(new_module)
  File "<frozen importlib._bootstrap_external>", line 843, in exec_module
  File "<frozen importlib._bootstrap>", line 219, in _call_with_frames_removed
  File "/opt/airflow/dags/scripts/kafka_pubsub.py", line 16, in <module>
    publisher = pubsub_v1.PublisherClient()
  File "/home/airflow/.local/lib/python3.8/site-packages/google/cloud/pubsub_v1/publisher/client.py", line 139, in __init__
    super().__init__(**kwargs)
  File "/home/airflow/.local/lib/python3.8/site-packages/google/pubsub_v1/services/publisher/client.py", line 492, in __init__
    self._transport = Transport(
  File "/home/airflow/.local/lib/python3.8/site-packages/google/pubsub_v1/services/publisher/transports/grpc.py", line 153, in __init__
    super().__init__(
  File "/home/airflow/.local/lib/python3.8/site-packages/google/pubsub_v1/services/publisher/transports/base.py", line 104, in __init__
    credentials, _ = google.auth.default(
  File "/home/airflow/.local/lib/python3.8/site-packages/google/auth/_default.py", line 659, in default
    credentials, project_id = checker()
  File "/home/airflow/.local/lib/python3.8/site-packages/google/auth/_default.py", line 652, in <lambda>
    lambda: _get_explicit_environ_credentials(quota_project_id=quota_project_id),
  File "/home/airflow/.local/lib/python3.8/site-packages/google/auth/_default.py", line 272, in _get_explicit_environ_credentials
    credentials, project_id = load_credentials_from_file(
  File "/home/airflow/.local/lib/python3.8/site-packages/google/auth/_default.py", line 116, in load_credentials_from_file
    raise exceptions.DefaultCredentialsError(
google.auth.exceptions.DefaultCredentialsError: File /Users/megwed./Desktop/airflow_local/ready-de-25-f50d96fb2977.json was not found.
[2024-12-16T18:36:59.621+0000] {processor.py:838} WARNING - No viable dags retrieved from /opt/airflow/dags/scripts/kafka_pubsub.py
[2024-12-16T18:36:59.634+0000] {processor.py:179} INFO - Processing /opt/airflow/dags/scripts/kafka_pubsub.py took 0.288 seconds
[2024-12-16T18:37:30.143+0000] {processor.py:157} INFO - Started process (PID=112) to work on /opt/airflow/dags/scripts/kafka_pubsub.py
[2024-12-16T18:37:30.144+0000] {processor.py:826} INFO - Processing file /opt/airflow/dags/scripts/kafka_pubsub.py for tasks to queue
[2024-12-16T18:37:30.145+0000] {logging_mixin.py:150} INFO - [2024-12-16T18:37:30.145+0000] {dagbag.py:541} INFO - Filling up the DagBag from /opt/airflow/dags/scripts/kafka_pubsub.py
[2024-12-16T18:37:30.464+0000] {logging_mixin.py:150} INFO - [2024-12-16T18:37:30.458+0000] {dagbag.py:350} ERROR - Failed to import: /opt/airflow/dags/scripts/kafka_pubsub.py
Traceback (most recent call last):
  File "/home/airflow/.local/lib/python3.8/site-packages/airflow/models/dagbag.py", line 346, in parse
    loader.exec_module(new_module)
  File "<frozen importlib._bootstrap_external>", line 843, in exec_module
  File "<frozen importlib._bootstrap>", line 219, in _call_with_frames_removed
  File "/opt/airflow/dags/scripts/kafka_pubsub.py", line 16, in <module>
    publisher = pubsub_v1.PublisherClient()
  File "/home/airflow/.local/lib/python3.8/site-packages/google/cloud/pubsub_v1/publisher/client.py", line 139, in __init__
    super().__init__(**kwargs)
  File "/home/airflow/.local/lib/python3.8/site-packages/google/pubsub_v1/services/publisher/client.py", line 492, in __init__
    self._transport = Transport(
  File "/home/airflow/.local/lib/python3.8/site-packages/google/pubsub_v1/services/publisher/transports/grpc.py", line 153, in __init__
    super().__init__(
  File "/home/airflow/.local/lib/python3.8/site-packages/google/pubsub_v1/services/publisher/transports/base.py", line 104, in __init__
    credentials, _ = google.auth.default(
  File "/home/airflow/.local/lib/python3.8/site-packages/google/auth/_default.py", line 659, in default
    credentials, project_id = checker()
  File "/home/airflow/.local/lib/python3.8/site-packages/google/auth/_default.py", line 652, in <lambda>
    lambda: _get_explicit_environ_credentials(quota_project_id=quota_project_id),
  File "/home/airflow/.local/lib/python3.8/site-packages/google/auth/_default.py", line 272, in _get_explicit_environ_credentials
    credentials, project_id = load_credentials_from_file(
  File "/home/airflow/.local/lib/python3.8/site-packages/google/auth/_default.py", line 116, in load_credentials_from_file
    raise exceptions.DefaultCredentialsError(
google.auth.exceptions.DefaultCredentialsError: File /Users/megwed./Desktop/airflow_local/ready-de-25-f50d96fb2977.json was not found.
[2024-12-16T18:37:30.465+0000] {processor.py:838} WARNING - No viable dags retrieved from /opt/airflow/dags/scripts/kafka_pubsub.py
[2024-12-16T18:37:30.495+0000] {processor.py:179} INFO - Processing /opt/airflow/dags/scripts/kafka_pubsub.py took 0.356 seconds
[2024-12-16T18:38:01.209+0000] {processor.py:157} INFO - Started process (PID=122) to work on /opt/airflow/dags/scripts/kafka_pubsub.py
[2024-12-16T18:38:01.212+0000] {processor.py:826} INFO - Processing file /opt/airflow/dags/scripts/kafka_pubsub.py for tasks to queue
[2024-12-16T18:38:01.213+0000] {logging_mixin.py:150} INFO - [2024-12-16T18:38:01.213+0000] {dagbag.py:541} INFO - Filling up the DagBag from /opt/airflow/dags/scripts/kafka_pubsub.py
[2024-12-16T18:38:01.467+0000] {logging_mixin.py:150} INFO - [2024-12-16T18:38:01.462+0000] {dagbag.py:350} ERROR - Failed to import: /opt/airflow/dags/scripts/kafka_pubsub.py
Traceback (most recent call last):
  File "/home/airflow/.local/lib/python3.8/site-packages/airflow/models/dagbag.py", line 346, in parse
    loader.exec_module(new_module)
  File "<frozen importlib._bootstrap_external>", line 843, in exec_module
  File "<frozen importlib._bootstrap>", line 219, in _call_with_frames_removed
  File "/opt/airflow/dags/scripts/kafka_pubsub.py", line 16, in <module>
    publisher = pubsub_v1.PublisherClient()
  File "/home/airflow/.local/lib/python3.8/site-packages/google/cloud/pubsub_v1/publisher/client.py", line 139, in __init__
    super().__init__(**kwargs)
  File "/home/airflow/.local/lib/python3.8/site-packages/google/pubsub_v1/services/publisher/client.py", line 492, in __init__
    self._transport = Transport(
  File "/home/airflow/.local/lib/python3.8/site-packages/google/pubsub_v1/services/publisher/transports/grpc.py", line 153, in __init__
    super().__init__(
  File "/home/airflow/.local/lib/python3.8/site-packages/google/pubsub_v1/services/publisher/transports/base.py", line 104, in __init__
    credentials, _ = google.auth.default(
  File "/home/airflow/.local/lib/python3.8/site-packages/google/auth/_default.py", line 659, in default
    credentials, project_id = checker()
  File "/home/airflow/.local/lib/python3.8/site-packages/google/auth/_default.py", line 652, in <lambda>
    lambda: _get_explicit_environ_credentials(quota_project_id=quota_project_id),
  File "/home/airflow/.local/lib/python3.8/site-packages/google/auth/_default.py", line 272, in _get_explicit_environ_credentials
    credentials, project_id = load_credentials_from_file(
  File "/home/airflow/.local/lib/python3.8/site-packages/google/auth/_default.py", line 116, in load_credentials_from_file
    raise exceptions.DefaultCredentialsError(
google.auth.exceptions.DefaultCredentialsError: File /Users/megwed./Desktop/airflow_local/ready-de-25-f50d96fb2977.json was not found.
[2024-12-16T18:38:01.469+0000] {processor.py:838} WARNING - No viable dags retrieved from /opt/airflow/dags/scripts/kafka_pubsub.py
[2024-12-16T18:38:01.485+0000] {processor.py:179} INFO - Processing /opt/airflow/dags/scripts/kafka_pubsub.py took 0.282 seconds
[2024-12-16T18:38:32.043+0000] {processor.py:157} INFO - Started process (PID=132) to work on /opt/airflow/dags/scripts/kafka_pubsub.py
[2024-12-16T18:38:32.047+0000] {processor.py:826} INFO - Processing file /opt/airflow/dags/scripts/kafka_pubsub.py for tasks to queue
[2024-12-16T18:38:32.048+0000] {logging_mixin.py:150} INFO - [2024-12-16T18:38:32.048+0000] {dagbag.py:541} INFO - Filling up the DagBag from /opt/airflow/dags/scripts/kafka_pubsub.py
[2024-12-16T18:38:32.277+0000] {logging_mixin.py:150} INFO - [2024-12-16T18:38:32.274+0000] {dagbag.py:350} ERROR - Failed to import: /opt/airflow/dags/scripts/kafka_pubsub.py
Traceback (most recent call last):
  File "/home/airflow/.local/lib/python3.8/site-packages/airflow/models/dagbag.py", line 346, in parse
    loader.exec_module(new_module)
  File "<frozen importlib._bootstrap_external>", line 843, in exec_module
  File "<frozen importlib._bootstrap>", line 219, in _call_with_frames_removed
  File "/opt/airflow/dags/scripts/kafka_pubsub.py", line 16, in <module>
    publisher = pubsub_v1.PublisherClient()
  File "/home/airflow/.local/lib/python3.8/site-packages/google/cloud/pubsub_v1/publisher/client.py", line 139, in __init__
    super().__init__(**kwargs)
  File "/home/airflow/.local/lib/python3.8/site-packages/google/pubsub_v1/services/publisher/client.py", line 492, in __init__
    self._transport = Transport(
  File "/home/airflow/.local/lib/python3.8/site-packages/google/pubsub_v1/services/publisher/transports/grpc.py", line 153, in __init__
    super().__init__(
  File "/home/airflow/.local/lib/python3.8/site-packages/google/pubsub_v1/services/publisher/transports/base.py", line 104, in __init__
    credentials, _ = google.auth.default(
  File "/home/airflow/.local/lib/python3.8/site-packages/google/auth/_default.py", line 659, in default
    credentials, project_id = checker()
  File "/home/airflow/.local/lib/python3.8/site-packages/google/auth/_default.py", line 652, in <lambda>
    lambda: _get_explicit_environ_credentials(quota_project_id=quota_project_id),
  File "/home/airflow/.local/lib/python3.8/site-packages/google/auth/_default.py", line 272, in _get_explicit_environ_credentials
    credentials, project_id = load_credentials_from_file(
  File "/home/airflow/.local/lib/python3.8/site-packages/google/auth/_default.py", line 116, in load_credentials_from_file
    raise exceptions.DefaultCredentialsError(
google.auth.exceptions.DefaultCredentialsError: File /Users/megwed./Desktop/airflow_local/ready-de-25-f50d96fb2977.json was not found.
[2024-12-16T18:38:32.277+0000] {processor.py:838} WARNING - No viable dags retrieved from /opt/airflow/dags/scripts/kafka_pubsub.py
[2024-12-16T18:38:32.288+0000] {processor.py:179} INFO - Processing /opt/airflow/dags/scripts/kafka_pubsub.py took 0.250 seconds
[2024-12-16T18:39:02.829+0000] {processor.py:157} INFO - Started process (PID=142) to work on /opt/airflow/dags/scripts/kafka_pubsub.py
[2024-12-16T18:39:02.831+0000] {processor.py:826} INFO - Processing file /opt/airflow/dags/scripts/kafka_pubsub.py for tasks to queue
[2024-12-16T18:39:02.833+0000] {logging_mixin.py:150} INFO - [2024-12-16T18:39:02.833+0000] {dagbag.py:541} INFO - Filling up the DagBag from /opt/airflow/dags/scripts/kafka_pubsub.py
[2024-12-16T18:39:03.080+0000] {logging_mixin.py:150} INFO - [2024-12-16T18:39:03.078+0000] {dagbag.py:350} ERROR - Failed to import: /opt/airflow/dags/scripts/kafka_pubsub.py
Traceback (most recent call last):
  File "/home/airflow/.local/lib/python3.8/site-packages/airflow/models/dagbag.py", line 346, in parse
    loader.exec_module(new_module)
  File "<frozen importlib._bootstrap_external>", line 843, in exec_module
  File "<frozen importlib._bootstrap>", line 219, in _call_with_frames_removed
  File "/opt/airflow/dags/scripts/kafka_pubsub.py", line 16, in <module>
    publisher = pubsub_v1.PublisherClient()
  File "/home/airflow/.local/lib/python3.8/site-packages/google/cloud/pubsub_v1/publisher/client.py", line 139, in __init__
    super().__init__(**kwargs)
  File "/home/airflow/.local/lib/python3.8/site-packages/google/pubsub_v1/services/publisher/client.py", line 492, in __init__
    self._transport = Transport(
  File "/home/airflow/.local/lib/python3.8/site-packages/google/pubsub_v1/services/publisher/transports/grpc.py", line 153, in __init__
    super().__init__(
  File "/home/airflow/.local/lib/python3.8/site-packages/google/pubsub_v1/services/publisher/transports/base.py", line 104, in __init__
    credentials, _ = google.auth.default(
  File "/home/airflow/.local/lib/python3.8/site-packages/google/auth/_default.py", line 659, in default
    credentials, project_id = checker()
  File "/home/airflow/.local/lib/python3.8/site-packages/google/auth/_default.py", line 652, in <lambda>
    lambda: _get_explicit_environ_credentials(quota_project_id=quota_project_id),
  File "/home/airflow/.local/lib/python3.8/site-packages/google/auth/_default.py", line 272, in _get_explicit_environ_credentials
    credentials, project_id = load_credentials_from_file(
  File "/home/airflow/.local/lib/python3.8/site-packages/google/auth/_default.py", line 116, in load_credentials_from_file
    raise exceptions.DefaultCredentialsError(
google.auth.exceptions.DefaultCredentialsError: File /Users/megwed./Desktop/airflow_local/ready-de-25-f50d96fb2977.json was not found.
[2024-12-16T18:39:03.081+0000] {processor.py:838} WARNING - No viable dags retrieved from /opt/airflow/dags/scripts/kafka_pubsub.py
[2024-12-16T18:39:03.093+0000] {processor.py:179} INFO - Processing /opt/airflow/dags/scripts/kafka_pubsub.py took 0.268 seconds
[2024-12-16T18:39:33.604+0000] {processor.py:157} INFO - Started process (PID=152) to work on /opt/airflow/dags/scripts/kafka_pubsub.py
[2024-12-16T18:39:33.606+0000] {processor.py:826} INFO - Processing file /opt/airflow/dags/scripts/kafka_pubsub.py for tasks to queue
[2024-12-16T18:39:33.607+0000] {logging_mixin.py:150} INFO - [2024-12-16T18:39:33.606+0000] {dagbag.py:541} INFO - Filling up the DagBag from /opt/airflow/dags/scripts/kafka_pubsub.py
[2024-12-16T18:39:33.834+0000] {logging_mixin.py:150} INFO - [2024-12-16T18:39:33.832+0000] {dagbag.py:350} ERROR - Failed to import: /opt/airflow/dags/scripts/kafka_pubsub.py
Traceback (most recent call last):
  File "/home/airflow/.local/lib/python3.8/site-packages/airflow/models/dagbag.py", line 346, in parse
    loader.exec_module(new_module)
  File "<frozen importlib._bootstrap_external>", line 843, in exec_module
  File "<frozen importlib._bootstrap>", line 219, in _call_with_frames_removed
  File "/opt/airflow/dags/scripts/kafka_pubsub.py", line 16, in <module>
    publisher = pubsub_v1.PublisherClient()
  File "/home/airflow/.local/lib/python3.8/site-packages/google/cloud/pubsub_v1/publisher/client.py", line 139, in __init__
    super().__init__(**kwargs)
  File "/home/airflow/.local/lib/python3.8/site-packages/google/pubsub_v1/services/publisher/client.py", line 492, in __init__
    self._transport = Transport(
  File "/home/airflow/.local/lib/python3.8/site-packages/google/pubsub_v1/services/publisher/transports/grpc.py", line 153, in __init__
    super().__init__(
  File "/home/airflow/.local/lib/python3.8/site-packages/google/pubsub_v1/services/publisher/transports/base.py", line 104, in __init__
    credentials, _ = google.auth.default(
  File "/home/airflow/.local/lib/python3.8/site-packages/google/auth/_default.py", line 659, in default
    credentials, project_id = checker()
  File "/home/airflow/.local/lib/python3.8/site-packages/google/auth/_default.py", line 652, in <lambda>
    lambda: _get_explicit_environ_credentials(quota_project_id=quota_project_id),
  File "/home/airflow/.local/lib/python3.8/site-packages/google/auth/_default.py", line 272, in _get_explicit_environ_credentials
    credentials, project_id = load_credentials_from_file(
  File "/home/airflow/.local/lib/python3.8/site-packages/google/auth/_default.py", line 116, in load_credentials_from_file
    raise exceptions.DefaultCredentialsError(
google.auth.exceptions.DefaultCredentialsError: File /Users/megwed./Desktop/airflow_local/ready-de-25-f50d96fb2977.json was not found.
[2024-12-16T18:39:33.835+0000] {processor.py:838} WARNING - No viable dags retrieved from /opt/airflow/dags/scripts/kafka_pubsub.py
[2024-12-16T18:39:33.851+0000] {processor.py:179} INFO - Processing /opt/airflow/dags/scripts/kafka_pubsub.py took 0.252 seconds
[2024-12-16T18:40:04.356+0000] {processor.py:157} INFO - Started process (PID=162) to work on /opt/airflow/dags/scripts/kafka_pubsub.py
[2024-12-16T18:40:04.359+0000] {processor.py:826} INFO - Processing file /opt/airflow/dags/scripts/kafka_pubsub.py for tasks to queue
[2024-12-16T18:40:04.361+0000] {logging_mixin.py:150} INFO - [2024-12-16T18:40:04.360+0000] {dagbag.py:541} INFO - Filling up the DagBag from /opt/airflow/dags/scripts/kafka_pubsub.py
[2024-12-16T18:40:04.585+0000] {logging_mixin.py:150} INFO - [2024-12-16T18:40:04.582+0000] {dagbag.py:350} ERROR - Failed to import: /opt/airflow/dags/scripts/kafka_pubsub.py
Traceback (most recent call last):
  File "/home/airflow/.local/lib/python3.8/site-packages/airflow/models/dagbag.py", line 346, in parse
    loader.exec_module(new_module)
  File "<frozen importlib._bootstrap_external>", line 843, in exec_module
  File "<frozen importlib._bootstrap>", line 219, in _call_with_frames_removed
  File "/opt/airflow/dags/scripts/kafka_pubsub.py", line 16, in <module>
    publisher = pubsub_v1.PublisherClient()
  File "/home/airflow/.local/lib/python3.8/site-packages/google/cloud/pubsub_v1/publisher/client.py", line 139, in __init__
    super().__init__(**kwargs)
  File "/home/airflow/.local/lib/python3.8/site-packages/google/pubsub_v1/services/publisher/client.py", line 492, in __init__
    self._transport = Transport(
  File "/home/airflow/.local/lib/python3.8/site-packages/google/pubsub_v1/services/publisher/transports/grpc.py", line 153, in __init__
    super().__init__(
  File "/home/airflow/.local/lib/python3.8/site-packages/google/pubsub_v1/services/publisher/transports/base.py", line 104, in __init__
    credentials, _ = google.auth.default(
  File "/home/airflow/.local/lib/python3.8/site-packages/google/auth/_default.py", line 659, in default
    credentials, project_id = checker()
  File "/home/airflow/.local/lib/python3.8/site-packages/google/auth/_default.py", line 652, in <lambda>
    lambda: _get_explicit_environ_credentials(quota_project_id=quota_project_id),
  File "/home/airflow/.local/lib/python3.8/site-packages/google/auth/_default.py", line 272, in _get_explicit_environ_credentials
    credentials, project_id = load_credentials_from_file(
  File "/home/airflow/.local/lib/python3.8/site-packages/google/auth/_default.py", line 116, in load_credentials_from_file
    raise exceptions.DefaultCredentialsError(
google.auth.exceptions.DefaultCredentialsError: File /Users/megwed./Desktop/airflow_local/ready-de-25-f50d96fb2977.json was not found.
[2024-12-16T18:40:04.585+0000] {processor.py:838} WARNING - No viable dags retrieved from /opt/airflow/dags/scripts/kafka_pubsub.py
[2024-12-16T18:40:04.598+0000] {processor.py:179} INFO - Processing /opt/airflow/dags/scripts/kafka_pubsub.py took 0.250 seconds
[2024-12-16T18:43:35.395+0000] {processor.py:157} INFO - Started process (PID=33) to work on /opt/airflow/dags/scripts/kafka_pubsub.py
[2024-12-16T18:43:35.397+0000] {processor.py:826} INFO - Processing file /opt/airflow/dags/scripts/kafka_pubsub.py for tasks to queue
[2024-12-16T18:43:35.402+0000] {logging_mixin.py:150} INFO - [2024-12-16T18:43:35.401+0000] {dagbag.py:541} INFO - Filling up the DagBag from /opt/airflow/dags/scripts/kafka_pubsub.py
[2024-12-16T18:43:35.940+0000] {logging_mixin.py:150} INFO - [2024-12-16T18:43:35.931+0000] {dagbag.py:350} ERROR - Failed to import: /opt/airflow/dags/scripts/kafka_pubsub.py
Traceback (most recent call last):
  File "/home/airflow/.local/lib/python3.8/site-packages/airflow/models/dagbag.py", line 346, in parse
    loader.exec_module(new_module)
  File "<frozen importlib._bootstrap_external>", line 843, in exec_module
  File "<frozen importlib._bootstrap>", line 219, in _call_with_frames_removed
  File "/opt/airflow/dags/scripts/kafka_pubsub.py", line 16, in <module>
    publisher = pubsub_v1.PublisherClient()
  File "/home/airflow/.local/lib/python3.8/site-packages/google/cloud/pubsub_v1/publisher/client.py", line 139, in __init__
    super().__init__(**kwargs)
  File "/home/airflow/.local/lib/python3.8/site-packages/google/pubsub_v1/services/publisher/client.py", line 492, in __init__
    self._transport = Transport(
  File "/home/airflow/.local/lib/python3.8/site-packages/google/pubsub_v1/services/publisher/transports/grpc.py", line 153, in __init__
    super().__init__(
  File "/home/airflow/.local/lib/python3.8/site-packages/google/pubsub_v1/services/publisher/transports/base.py", line 104, in __init__
    credentials, _ = google.auth.default(
  File "/home/airflow/.local/lib/python3.8/site-packages/google/auth/_default.py", line 659, in default
    credentials, project_id = checker()
  File "/home/airflow/.local/lib/python3.8/site-packages/google/auth/_default.py", line 652, in <lambda>
    lambda: _get_explicit_environ_credentials(quota_project_id=quota_project_id),
  File "/home/airflow/.local/lib/python3.8/site-packages/google/auth/_default.py", line 272, in _get_explicit_environ_credentials
    credentials, project_id = load_credentials_from_file(
  File "/home/airflow/.local/lib/python3.8/site-packages/google/auth/_default.py", line 116, in load_credentials_from_file
    raise exceptions.DefaultCredentialsError(
google.auth.exceptions.DefaultCredentialsError: File /Users/megwed./Desktop/airflow_local/ready-de-25-f50d96fb2977.json was not found.
[2024-12-16T18:43:35.942+0000] {processor.py:838} WARNING - No viable dags retrieved from /opt/airflow/dags/scripts/kafka_pubsub.py
[2024-12-16T18:43:35.994+0000] {processor.py:179} INFO - Processing /opt/airflow/dags/scripts/kafka_pubsub.py took 0.605 seconds
[2024-12-16T18:44:06.725+0000] {processor.py:157} INFO - Started process (PID=43) to work on /opt/airflow/dags/scripts/kafka_pubsub.py
[2024-12-16T18:44:06.726+0000] {processor.py:826} INFO - Processing file /opt/airflow/dags/scripts/kafka_pubsub.py for tasks to queue
[2024-12-16T18:44:06.727+0000] {logging_mixin.py:150} INFO - [2024-12-16T18:44:06.727+0000] {dagbag.py:541} INFO - Filling up the DagBag from /opt/airflow/dags/scripts/kafka_pubsub.py
[2024-12-16T18:44:06.823+0000] {logging_mixin.py:150} INFO - [2024-12-16T18:44:06.819+0000] {dagbag.py:350} ERROR - Failed to import: /opt/airflow/dags/scripts/kafka_pubsub.py
Traceback (most recent call last):
  File "/home/airflow/.local/lib/python3.8/site-packages/airflow/models/dagbag.py", line 346, in parse
    loader.exec_module(new_module)
  File "<frozen importlib._bootstrap_external>", line 843, in exec_module
  File "<frozen importlib._bootstrap>", line 219, in _call_with_frames_removed
  File "/opt/airflow/dags/scripts/kafka_pubsub.py", line 16, in <module>
    publisher = pubsub_v1.PublisherClient()
  File "/home/airflow/.local/lib/python3.8/site-packages/google/cloud/pubsub_v1/publisher/client.py", line 139, in __init__
    super().__init__(**kwargs)
  File "/home/airflow/.local/lib/python3.8/site-packages/google/pubsub_v1/services/publisher/client.py", line 492, in __init__
    self._transport = Transport(
  File "/home/airflow/.local/lib/python3.8/site-packages/google/pubsub_v1/services/publisher/transports/grpc.py", line 153, in __init__
    super().__init__(
  File "/home/airflow/.local/lib/python3.8/site-packages/google/pubsub_v1/services/publisher/transports/base.py", line 104, in __init__
    credentials, _ = google.auth.default(
  File "/home/airflow/.local/lib/python3.8/site-packages/google/auth/_default.py", line 659, in default
    credentials, project_id = checker()
  File "/home/airflow/.local/lib/python3.8/site-packages/google/auth/_default.py", line 652, in <lambda>
    lambda: _get_explicit_environ_credentials(quota_project_id=quota_project_id),
  File "/home/airflow/.local/lib/python3.8/site-packages/google/auth/_default.py", line 272, in _get_explicit_environ_credentials
    credentials, project_id = load_credentials_from_file(
  File "/home/airflow/.local/lib/python3.8/site-packages/google/auth/_default.py", line 116, in load_credentials_from_file
    raise exceptions.DefaultCredentialsError(
google.auth.exceptions.DefaultCredentialsError: File /Users/megwed./Desktop/airflow_local/ready-de-25-f50d96fb2977.json was not found.
[2024-12-16T18:44:06.823+0000] {processor.py:838} WARNING - No viable dags retrieved from /opt/airflow/dags/scripts/kafka_pubsub.py
[2024-12-16T18:44:06.841+0000] {processor.py:179} INFO - Processing /opt/airflow/dags/scripts/kafka_pubsub.py took 0.119 seconds
[2024-12-16T18:44:37.325+0000] {processor.py:157} INFO - Started process (PID=53) to work on /opt/airflow/dags/scripts/kafka_pubsub.py
[2024-12-16T18:44:37.326+0000] {processor.py:826} INFO - Processing file /opt/airflow/dags/scripts/kafka_pubsub.py for tasks to queue
[2024-12-16T18:44:37.327+0000] {logging_mixin.py:150} INFO - [2024-12-16T18:44:37.327+0000] {dagbag.py:541} INFO - Filling up the DagBag from /opt/airflow/dags/scripts/kafka_pubsub.py
[2024-12-16T18:44:37.637+0000] {logging_mixin.py:150} INFO - [2024-12-16T18:44:37.634+0000] {dagbag.py:350} ERROR - Failed to import: /opt/airflow/dags/scripts/kafka_pubsub.py
Traceback (most recent call last):
  File "/home/airflow/.local/lib/python3.8/site-packages/airflow/models/dagbag.py", line 346, in parse
    loader.exec_module(new_module)
  File "<frozen importlib._bootstrap_external>", line 843, in exec_module
  File "<frozen importlib._bootstrap>", line 219, in _call_with_frames_removed
  File "/opt/airflow/dags/scripts/kafka_pubsub.py", line 16, in <module>
    publisher = pubsub_v1.PublisherClient()
  File "/home/airflow/.local/lib/python3.8/site-packages/google/cloud/pubsub_v1/publisher/client.py", line 139, in __init__
    super().__init__(**kwargs)
  File "/home/airflow/.local/lib/python3.8/site-packages/google/pubsub_v1/services/publisher/client.py", line 492, in __init__
    self._transport = Transport(
  File "/home/airflow/.local/lib/python3.8/site-packages/google/pubsub_v1/services/publisher/transports/grpc.py", line 153, in __init__
    super().__init__(
  File "/home/airflow/.local/lib/python3.8/site-packages/google/pubsub_v1/services/publisher/transports/base.py", line 104, in __init__
    credentials, _ = google.auth.default(
  File "/home/airflow/.local/lib/python3.8/site-packages/google/auth/_default.py", line 659, in default
    credentials, project_id = checker()
  File "/home/airflow/.local/lib/python3.8/site-packages/google/auth/_default.py", line 652, in <lambda>
    lambda: _get_explicit_environ_credentials(quota_project_id=quota_project_id),
  File "/home/airflow/.local/lib/python3.8/site-packages/google/auth/_default.py", line 272, in _get_explicit_environ_credentials
    credentials, project_id = load_credentials_from_file(
  File "/home/airflow/.local/lib/python3.8/site-packages/google/auth/_default.py", line 116, in load_credentials_from_file
    raise exceptions.DefaultCredentialsError(
google.auth.exceptions.DefaultCredentialsError: File /Users/megwed./Desktop/airflow_local/ready-de-25-f50d96fb2977.json was not found.
[2024-12-16T18:44:37.638+0000] {processor.py:838} WARNING - No viable dags retrieved from /opt/airflow/dags/scripts/kafka_pubsub.py
[2024-12-16T18:44:37.664+0000] {processor.py:179} INFO - Processing /opt/airflow/dags/scripts/kafka_pubsub.py took 0.342 seconds
[2024-12-16T18:45:53.866+0000] {processor.py:157} INFO - Started process (PID=33) to work on /opt/airflow/dags/scripts/kafka_pubsub.py
[2024-12-16T18:45:53.867+0000] {processor.py:826} INFO - Processing file /opt/airflow/dags/scripts/kafka_pubsub.py for tasks to queue
[2024-12-16T18:45:53.868+0000] {logging_mixin.py:150} INFO - [2024-12-16T18:45:53.868+0000] {dagbag.py:541} INFO - Filling up the DagBag from /opt/airflow/dags/scripts/kafka_pubsub.py
[2024-12-16T18:45:54.586+0000] {logging_mixin.py:150} INFO - [2024-12-16T18:45:54.573+0000] {dagbag.py:350} ERROR - Failed to import: /opt/airflow/dags/scripts/kafka_pubsub.py
Traceback (most recent call last):
  File "/home/airflow/.local/lib/python3.8/site-packages/airflow/models/dagbag.py", line 346, in parse
    loader.exec_module(new_module)
  File "<frozen importlib._bootstrap_external>", line 843, in exec_module
  File "<frozen importlib._bootstrap>", line 219, in _call_with_frames_removed
  File "/opt/airflow/dags/scripts/kafka_pubsub.py", line 16, in <module>
    publisher = pubsub_v1.PublisherClient()
  File "/home/airflow/.local/lib/python3.8/site-packages/google/cloud/pubsub_v1/publisher/client.py", line 139, in __init__
    super().__init__(**kwargs)
  File "/home/airflow/.local/lib/python3.8/site-packages/google/pubsub_v1/services/publisher/client.py", line 492, in __init__
    self._transport = Transport(
  File "/home/airflow/.local/lib/python3.8/site-packages/google/pubsub_v1/services/publisher/transports/grpc.py", line 153, in __init__
    super().__init__(
  File "/home/airflow/.local/lib/python3.8/site-packages/google/pubsub_v1/services/publisher/transports/base.py", line 104, in __init__
    credentials, _ = google.auth.default(
  File "/home/airflow/.local/lib/python3.8/site-packages/google/auth/_default.py", line 659, in default
    credentials, project_id = checker()
  File "/home/airflow/.local/lib/python3.8/site-packages/google/auth/_default.py", line 652, in <lambda>
    lambda: _get_explicit_environ_credentials(quota_project_id=quota_project_id),
  File "/home/airflow/.local/lib/python3.8/site-packages/google/auth/_default.py", line 272, in _get_explicit_environ_credentials
    credentials, project_id = load_credentials_from_file(
  File "/home/airflow/.local/lib/python3.8/site-packages/google/auth/_default.py", line 116, in load_credentials_from_file
    raise exceptions.DefaultCredentialsError(
google.auth.exceptions.DefaultCredentialsError: File /Users/megwed./Desktop/airflow_local/ready-de-25-f50d96fb2977.json was not found.
[2024-12-16T18:45:54.587+0000] {processor.py:838} WARNING - No viable dags retrieved from /opt/airflow/dags/scripts/kafka_pubsub.py
[2024-12-16T18:45:54.625+0000] {processor.py:179} INFO - Processing /opt/airflow/dags/scripts/kafka_pubsub.py took 0.761 seconds
[2024-12-16T18:46:35.903+0000] {processor.py:157} INFO - Started process (PID=33) to work on /opt/airflow/dags/scripts/kafka_pubsub.py
[2024-12-16T18:46:35.908+0000] {processor.py:826} INFO - Processing file /opt/airflow/dags/scripts/kafka_pubsub.py for tasks to queue
[2024-12-16T18:46:35.909+0000] {logging_mixin.py:150} INFO - [2024-12-16T18:46:35.909+0000] {dagbag.py:541} INFO - Filling up the DagBag from /opt/airflow/dags/scripts/kafka_pubsub.py
[2024-12-16T18:46:36.511+0000] {logging_mixin.py:150} INFO - [2024-12-16T18:46:36.504+0000] {dagbag.py:350} ERROR - Failed to import: /opt/airflow/dags/scripts/kafka_pubsub.py
Traceback (most recent call last):
  File "/home/airflow/.local/lib/python3.8/site-packages/airflow/models/dagbag.py", line 346, in parse
    loader.exec_module(new_module)
  File "<frozen importlib._bootstrap_external>", line 843, in exec_module
  File "<frozen importlib._bootstrap>", line 219, in _call_with_frames_removed
  File "/opt/airflow/dags/scripts/kafka_pubsub.py", line 16, in <module>
    publisher = pubsub_v1.PublisherClient()
  File "/home/airflow/.local/lib/python3.8/site-packages/google/cloud/pubsub_v1/publisher/client.py", line 139, in __init__
    super().__init__(**kwargs)
  File "/home/airflow/.local/lib/python3.8/site-packages/google/pubsub_v1/services/publisher/client.py", line 492, in __init__
    self._transport = Transport(
  File "/home/airflow/.local/lib/python3.8/site-packages/google/pubsub_v1/services/publisher/transports/grpc.py", line 153, in __init__
    super().__init__(
  File "/home/airflow/.local/lib/python3.8/site-packages/google/pubsub_v1/services/publisher/transports/base.py", line 104, in __init__
    credentials, _ = google.auth.default(
  File "/home/airflow/.local/lib/python3.8/site-packages/google/auth/_default.py", line 659, in default
    credentials, project_id = checker()
  File "/home/airflow/.local/lib/python3.8/site-packages/google/auth/_default.py", line 652, in <lambda>
    lambda: _get_explicit_environ_credentials(quota_project_id=quota_project_id),
  File "/home/airflow/.local/lib/python3.8/site-packages/google/auth/_default.py", line 272, in _get_explicit_environ_credentials
    credentials, project_id = load_credentials_from_file(
  File "/home/airflow/.local/lib/python3.8/site-packages/google/auth/_default.py", line 116, in load_credentials_from_file
    raise exceptions.DefaultCredentialsError(
google.auth.exceptions.DefaultCredentialsError: File /Users/megwed./Desktop/airflow_local/ready-de-25-f50d96fb2977.json was not found.
[2024-12-16T18:46:36.511+0000] {processor.py:838} WARNING - No viable dags retrieved from /opt/airflow/dags/scripts/kafka_pubsub.py
[2024-12-16T18:46:36.560+0000] {processor.py:179} INFO - Processing /opt/airflow/dags/scripts/kafka_pubsub.py took 0.661 seconds
[2024-12-16T18:47:07.115+0000] {processor.py:157} INFO - Started process (PID=43) to work on /opt/airflow/dags/scripts/kafka_pubsub.py
[2024-12-16T18:47:07.116+0000] {processor.py:826} INFO - Processing file /opt/airflow/dags/scripts/kafka_pubsub.py for tasks to queue
[2024-12-16T18:47:07.116+0000] {logging_mixin.py:150} INFO - [2024-12-16T18:47:07.116+0000] {dagbag.py:541} INFO - Filling up the DagBag from /opt/airflow/dags/scripts/kafka_pubsub.py
[2024-12-16T18:47:07.198+0000] {logging_mixin.py:150} INFO - [2024-12-16T18:47:07.195+0000] {dagbag.py:350} ERROR - Failed to import: /opt/airflow/dags/scripts/kafka_pubsub.py
Traceback (most recent call last):
  File "/home/airflow/.local/lib/python3.8/site-packages/airflow/models/dagbag.py", line 346, in parse
    loader.exec_module(new_module)
  File "<frozen importlib._bootstrap_external>", line 843, in exec_module
  File "<frozen importlib._bootstrap>", line 219, in _call_with_frames_removed
  File "/opt/airflow/dags/scripts/kafka_pubsub.py", line 16, in <module>
    publisher = pubsub_v1.PublisherClient()
  File "/home/airflow/.local/lib/python3.8/site-packages/google/cloud/pubsub_v1/publisher/client.py", line 139, in __init__
    super().__init__(**kwargs)
  File "/home/airflow/.local/lib/python3.8/site-packages/google/pubsub_v1/services/publisher/client.py", line 492, in __init__
    self._transport = Transport(
  File "/home/airflow/.local/lib/python3.8/site-packages/google/pubsub_v1/services/publisher/transports/grpc.py", line 153, in __init__
    super().__init__(
  File "/home/airflow/.local/lib/python3.8/site-packages/google/pubsub_v1/services/publisher/transports/base.py", line 104, in __init__
    credentials, _ = google.auth.default(
  File "/home/airflow/.local/lib/python3.8/site-packages/google/auth/_default.py", line 659, in default
    credentials, project_id = checker()
  File "/home/airflow/.local/lib/python3.8/site-packages/google/auth/_default.py", line 652, in <lambda>
    lambda: _get_explicit_environ_credentials(quota_project_id=quota_project_id),
  File "/home/airflow/.local/lib/python3.8/site-packages/google/auth/_default.py", line 272, in _get_explicit_environ_credentials
    credentials, project_id = load_credentials_from_file(
  File "/home/airflow/.local/lib/python3.8/site-packages/google/auth/_default.py", line 116, in load_credentials_from_file
    raise exceptions.DefaultCredentialsError(
google.auth.exceptions.DefaultCredentialsError: File /Users/megwed./Desktop/airflow_local/ready-de-25-f50d96fb2977.json was not found.
[2024-12-16T18:47:07.199+0000] {processor.py:838} WARNING - No viable dags retrieved from /opt/airflow/dags/scripts/kafka_pubsub.py
[2024-12-16T18:47:07.214+0000] {processor.py:179} INFO - Processing /opt/airflow/dags/scripts/kafka_pubsub.py took 0.100 seconds
[2024-12-16T18:47:37.777+0000] {processor.py:157} INFO - Started process (PID=53) to work on /opt/airflow/dags/scripts/kafka_pubsub.py
[2024-12-16T18:47:37.779+0000] {processor.py:826} INFO - Processing file /opt/airflow/dags/scripts/kafka_pubsub.py for tasks to queue
[2024-12-16T18:47:37.780+0000] {logging_mixin.py:150} INFO - [2024-12-16T18:47:37.780+0000] {dagbag.py:541} INFO - Filling up the DagBag from /opt/airflow/dags/scripts/kafka_pubsub.py
[2024-12-16T18:47:38.220+0000] {logging_mixin.py:150} INFO - [2024-12-16T18:47:38.216+0000] {dagbag.py:350} ERROR - Failed to import: /opt/airflow/dags/scripts/kafka_pubsub.py
Traceback (most recent call last):
  File "/home/airflow/.local/lib/python3.8/site-packages/airflow/models/dagbag.py", line 346, in parse
    loader.exec_module(new_module)
  File "<frozen importlib._bootstrap_external>", line 843, in exec_module
  File "<frozen importlib._bootstrap>", line 219, in _call_with_frames_removed
  File "/opt/airflow/dags/scripts/kafka_pubsub.py", line 16, in <module>
    publisher = pubsub_v1.PublisherClient()
  File "/home/airflow/.local/lib/python3.8/site-packages/google/cloud/pubsub_v1/publisher/client.py", line 139, in __init__
    super().__init__(**kwargs)
  File "/home/airflow/.local/lib/python3.8/site-packages/google/pubsub_v1/services/publisher/client.py", line 492, in __init__
    self._transport = Transport(
  File "/home/airflow/.local/lib/python3.8/site-packages/google/pubsub_v1/services/publisher/transports/grpc.py", line 153, in __init__
    super().__init__(
  File "/home/airflow/.local/lib/python3.8/site-packages/google/pubsub_v1/services/publisher/transports/base.py", line 104, in __init__
    credentials, _ = google.auth.default(
  File "/home/airflow/.local/lib/python3.8/site-packages/google/auth/_default.py", line 659, in default
    credentials, project_id = checker()
  File "/home/airflow/.local/lib/python3.8/site-packages/google/auth/_default.py", line 652, in <lambda>
    lambda: _get_explicit_environ_credentials(quota_project_id=quota_project_id),
  File "/home/airflow/.local/lib/python3.8/site-packages/google/auth/_default.py", line 272, in _get_explicit_environ_credentials
    credentials, project_id = load_credentials_from_file(
  File "/home/airflow/.local/lib/python3.8/site-packages/google/auth/_default.py", line 116, in load_credentials_from_file
    raise exceptions.DefaultCredentialsError(
google.auth.exceptions.DefaultCredentialsError: File /Users/megwed./Desktop/airflow_local/ready-de-25-f50d96fb2977.json was not found.
[2024-12-16T18:47:38.220+0000] {processor.py:838} WARNING - No viable dags retrieved from /opt/airflow/dags/scripts/kafka_pubsub.py
[2024-12-16T18:47:38.236+0000] {processor.py:179} INFO - Processing /opt/airflow/dags/scripts/kafka_pubsub.py took 0.464 seconds
[2024-12-16T18:48:08.762+0000] {processor.py:157} INFO - Started process (PID=63) to work on /opt/airflow/dags/scripts/kafka_pubsub.py
[2024-12-16T18:48:08.763+0000] {processor.py:826} INFO - Processing file /opt/airflow/dags/scripts/kafka_pubsub.py for tasks to queue
[2024-12-16T18:48:08.765+0000] {logging_mixin.py:150} INFO - [2024-12-16T18:48:08.765+0000] {dagbag.py:541} INFO - Filling up the DagBag from /opt/airflow/dags/scripts/kafka_pubsub.py
[2024-12-16T18:48:08.997+0000] {logging_mixin.py:150} INFO - [2024-12-16T18:48:08.989+0000] {dagbag.py:350} ERROR - Failed to import: /opt/airflow/dags/scripts/kafka_pubsub.py
Traceback (most recent call last):
  File "/home/airflow/.local/lib/python3.8/site-packages/airflow/models/dagbag.py", line 346, in parse
    loader.exec_module(new_module)
  File "<frozen importlib._bootstrap_external>", line 843, in exec_module
  File "<frozen importlib._bootstrap>", line 219, in _call_with_frames_removed
  File "/opt/airflow/dags/scripts/kafka_pubsub.py", line 16, in <module>
    publisher = pubsub_v1.PublisherClient()
  File "/home/airflow/.local/lib/python3.8/site-packages/google/cloud/pubsub_v1/publisher/client.py", line 139, in __init__
    super().__init__(**kwargs)
  File "/home/airflow/.local/lib/python3.8/site-packages/google/pubsub_v1/services/publisher/client.py", line 492, in __init__
    self._transport = Transport(
  File "/home/airflow/.local/lib/python3.8/site-packages/google/pubsub_v1/services/publisher/transports/grpc.py", line 153, in __init__
    super().__init__(
  File "/home/airflow/.local/lib/python3.8/site-packages/google/pubsub_v1/services/publisher/transports/base.py", line 104, in __init__
    credentials, _ = google.auth.default(
  File "/home/airflow/.local/lib/python3.8/site-packages/google/auth/_default.py", line 659, in default
    credentials, project_id = checker()
  File "/home/airflow/.local/lib/python3.8/site-packages/google/auth/_default.py", line 652, in <lambda>
    lambda: _get_explicit_environ_credentials(quota_project_id=quota_project_id),
  File "/home/airflow/.local/lib/python3.8/site-packages/google/auth/_default.py", line 272, in _get_explicit_environ_credentials
    credentials, project_id = load_credentials_from_file(
  File "/home/airflow/.local/lib/python3.8/site-packages/google/auth/_default.py", line 116, in load_credentials_from_file
    raise exceptions.DefaultCredentialsError(
google.auth.exceptions.DefaultCredentialsError: File /Users/megwed./Desktop/airflow_local/ready-de-25-f50d96fb2977.json was not found.
[2024-12-16T18:48:08.997+0000] {processor.py:838} WARNING - No viable dags retrieved from /opt/airflow/dags/scripts/kafka_pubsub.py
[2024-12-16T18:48:09.009+0000] {processor.py:179} INFO - Processing /opt/airflow/dags/scripts/kafka_pubsub.py took 0.251 seconds
[2024-12-16T18:48:39.512+0000] {processor.py:157} INFO - Started process (PID=73) to work on /opt/airflow/dags/scripts/kafka_pubsub.py
[2024-12-16T18:48:39.514+0000] {processor.py:826} INFO - Processing file /opt/airflow/dags/scripts/kafka_pubsub.py for tasks to queue
[2024-12-16T18:48:39.515+0000] {logging_mixin.py:150} INFO - [2024-12-16T18:48:39.515+0000] {dagbag.py:541} INFO - Filling up the DagBag from /opt/airflow/dags/scripts/kafka_pubsub.py
[2024-12-16T18:48:39.892+0000] {logging_mixin.py:150} INFO - [2024-12-16T18:48:39.889+0000] {dagbag.py:350} ERROR - Failed to import: /opt/airflow/dags/scripts/kafka_pubsub.py
Traceback (most recent call last):
  File "/home/airflow/.local/lib/python3.8/site-packages/airflow/models/dagbag.py", line 346, in parse
    loader.exec_module(new_module)
  File "<frozen importlib._bootstrap_external>", line 843, in exec_module
  File "<frozen importlib._bootstrap>", line 219, in _call_with_frames_removed
  File "/opt/airflow/dags/scripts/kafka_pubsub.py", line 16, in <module>
    publisher = pubsub_v1.PublisherClient()
  File "/home/airflow/.local/lib/python3.8/site-packages/google/cloud/pubsub_v1/publisher/client.py", line 139, in __init__
    super().__init__(**kwargs)
  File "/home/airflow/.local/lib/python3.8/site-packages/google/pubsub_v1/services/publisher/client.py", line 492, in __init__
    self._transport = Transport(
  File "/home/airflow/.local/lib/python3.8/site-packages/google/pubsub_v1/services/publisher/transports/grpc.py", line 153, in __init__
    super().__init__(
  File "/home/airflow/.local/lib/python3.8/site-packages/google/pubsub_v1/services/publisher/transports/base.py", line 104, in __init__
    credentials, _ = google.auth.default(
  File "/home/airflow/.local/lib/python3.8/site-packages/google/auth/_default.py", line 659, in default
    credentials, project_id = checker()
  File "/home/airflow/.local/lib/python3.8/site-packages/google/auth/_default.py", line 652, in <lambda>
    lambda: _get_explicit_environ_credentials(quota_project_id=quota_project_id),
  File "/home/airflow/.local/lib/python3.8/site-packages/google/auth/_default.py", line 272, in _get_explicit_environ_credentials
    credentials, project_id = load_credentials_from_file(
  File "/home/airflow/.local/lib/python3.8/site-packages/google/auth/_default.py", line 116, in load_credentials_from_file
    raise exceptions.DefaultCredentialsError(
google.auth.exceptions.DefaultCredentialsError: File /Users/megwed./Desktop/airflow_local/ready-de-25-f50d96fb2977.json was not found.
[2024-12-16T18:48:39.893+0000] {processor.py:838} WARNING - No viable dags retrieved from /opt/airflow/dags/scripts/kafka_pubsub.py
[2024-12-16T18:48:39.917+0000] {processor.py:179} INFO - Processing /opt/airflow/dags/scripts/kafka_pubsub.py took 0.413 seconds
[2024-12-16T18:49:10.034+0000] {processor.py:157} INFO - Started process (PID=83) to work on /opt/airflow/dags/scripts/kafka_pubsub.py
[2024-12-16T18:49:10.037+0000] {processor.py:826} INFO - Processing file /opt/airflow/dags/scripts/kafka_pubsub.py for tasks to queue
[2024-12-16T18:49:10.038+0000] {logging_mixin.py:150} INFO - [2024-12-16T18:49:10.037+0000] {dagbag.py:541} INFO - Filling up the DagBag from /opt/airflow/dags/scripts/kafka_pubsub.py
[2024-12-16T18:49:10.425+0000] {logging_mixin.py:150} INFO - [2024-12-16T18:49:10.420+0000] {dagbag.py:350} ERROR - Failed to import: /opt/airflow/dags/scripts/kafka_pubsub.py
Traceback (most recent call last):
  File "/home/airflow/.local/lib/python3.8/site-packages/airflow/models/dagbag.py", line 346, in parse
    loader.exec_module(new_module)
  File "<frozen importlib._bootstrap_external>", line 843, in exec_module
  File "<frozen importlib._bootstrap>", line 219, in _call_with_frames_removed
  File "/opt/airflow/dags/scripts/kafka_pubsub.py", line 16, in <module>
    publisher = pubsub_v1.PublisherClient()
  File "/home/airflow/.local/lib/python3.8/site-packages/google/cloud/pubsub_v1/publisher/client.py", line 139, in __init__
    super().__init__(**kwargs)
  File "/home/airflow/.local/lib/python3.8/site-packages/google/pubsub_v1/services/publisher/client.py", line 492, in __init__
    self._transport = Transport(
  File "/home/airflow/.local/lib/python3.8/site-packages/google/pubsub_v1/services/publisher/transports/grpc.py", line 153, in __init__
    super().__init__(
  File "/home/airflow/.local/lib/python3.8/site-packages/google/pubsub_v1/services/publisher/transports/base.py", line 104, in __init__
    credentials, _ = google.auth.default(
  File "/home/airflow/.local/lib/python3.8/site-packages/google/auth/_default.py", line 659, in default
    credentials, project_id = checker()
  File "/home/airflow/.local/lib/python3.8/site-packages/google/auth/_default.py", line 652, in <lambda>
    lambda: _get_explicit_environ_credentials(quota_project_id=quota_project_id),
  File "/home/airflow/.local/lib/python3.8/site-packages/google/auth/_default.py", line 272, in _get_explicit_environ_credentials
    credentials, project_id = load_credentials_from_file(
  File "/home/airflow/.local/lib/python3.8/site-packages/google/auth/_default.py", line 116, in load_credentials_from_file
    raise exceptions.DefaultCredentialsError(
google.auth.exceptions.DefaultCredentialsError: File /Users/megwed./Desktop/airflow_local/ready-de-25-f50d96fb2977.json was not found.
[2024-12-16T18:49:10.426+0000] {processor.py:838} WARNING - No viable dags retrieved from /opt/airflow/dags/scripts/kafka_pubsub.py
[2024-12-16T18:49:10.447+0000] {processor.py:179} INFO - Processing /opt/airflow/dags/scripts/kafka_pubsub.py took 0.416 seconds
[2024-12-16T18:49:41.021+0000] {processor.py:157} INFO - Started process (PID=93) to work on /opt/airflow/dags/scripts/kafka_pubsub.py
[2024-12-16T18:49:41.023+0000] {processor.py:826} INFO - Processing file /opt/airflow/dags/scripts/kafka_pubsub.py for tasks to queue
[2024-12-16T18:49:41.024+0000] {logging_mixin.py:150} INFO - [2024-12-16T18:49:41.023+0000] {dagbag.py:541} INFO - Filling up the DagBag from /opt/airflow/dags/scripts/kafka_pubsub.py
[2024-12-16T18:49:41.284+0000] {logging_mixin.py:150} INFO - [2024-12-16T18:49:41.280+0000] {dagbag.py:350} ERROR - Failed to import: /opt/airflow/dags/scripts/kafka_pubsub.py
Traceback (most recent call last):
  File "/home/airflow/.local/lib/python3.8/site-packages/airflow/models/dagbag.py", line 346, in parse
    loader.exec_module(new_module)
  File "<frozen importlib._bootstrap_external>", line 843, in exec_module
  File "<frozen importlib._bootstrap>", line 219, in _call_with_frames_removed
  File "/opt/airflow/dags/scripts/kafka_pubsub.py", line 16, in <module>
    publisher = pubsub_v1.PublisherClient()
  File "/home/airflow/.local/lib/python3.8/site-packages/google/cloud/pubsub_v1/publisher/client.py", line 139, in __init__
    super().__init__(**kwargs)
  File "/home/airflow/.local/lib/python3.8/site-packages/google/pubsub_v1/services/publisher/client.py", line 492, in __init__
    self._transport = Transport(
  File "/home/airflow/.local/lib/python3.8/site-packages/google/pubsub_v1/services/publisher/transports/grpc.py", line 153, in __init__
    super().__init__(
  File "/home/airflow/.local/lib/python3.8/site-packages/google/pubsub_v1/services/publisher/transports/base.py", line 104, in __init__
    credentials, _ = google.auth.default(
  File "/home/airflow/.local/lib/python3.8/site-packages/google/auth/_default.py", line 659, in default
    credentials, project_id = checker()
  File "/home/airflow/.local/lib/python3.8/site-packages/google/auth/_default.py", line 652, in <lambda>
    lambda: _get_explicit_environ_credentials(quota_project_id=quota_project_id),
  File "/home/airflow/.local/lib/python3.8/site-packages/google/auth/_default.py", line 272, in _get_explicit_environ_credentials
    credentials, project_id = load_credentials_from_file(
  File "/home/airflow/.local/lib/python3.8/site-packages/google/auth/_default.py", line 116, in load_credentials_from_file
    raise exceptions.DefaultCredentialsError(
google.auth.exceptions.DefaultCredentialsError: File /Users/megwed./Desktop/airflow_local/ready-de-25-f50d96fb2977.json was not found.
[2024-12-16T18:49:41.284+0000] {processor.py:838} WARNING - No viable dags retrieved from /opt/airflow/dags/scripts/kafka_pubsub.py
[2024-12-16T18:49:41.297+0000] {processor.py:179} INFO - Processing /opt/airflow/dags/scripts/kafka_pubsub.py took 0.282 seconds
